Workbook
Name Clientes: [1]Referencias!$B$7:$C$12
Name Clientes: [2]Referencias!$B$7:$C$50
Name Clientes: [3]Referencias!$B$7:$C$82
Name Clientes: [1]Referencias!$B$7:$C$12
Name Clientes: Referencias!$B$7:$C$154
Name imputacion: #REF!
Name imputacion: #REF!
Name imputacion: #REF!

Sheet Trabajos
B2: Trabajos
G3: Total | H3: =SUBTOTAL(9,H5:H394) -> 57801 | O3: Total | P3: =SUBTOTAL(9,P5:P394) -> 2.2427234e+08
B4: Fecha | C4: Cod. Trabajo | D4: Tipo de trabajo | E4: Cod. Cliente | F4: Cliente | G4: Establecimiento | H4: Superficie | I4: $/Ha | J4: Subtotal | K4: Cod. Vehiculo | L4: Vehiculo | M4: Distancia | N4: $/Km | O4: Movilidad | P4: Importe | R4: Paco | S4: Tomas | T4: Zoom | U4: Personas
B5: 45909 | C5: 1 | D5: =IFERROR(VLOOKUP(Trabajos!C5,Referencias!$E$7:$F$30,2,FALSE),"") -> Muestreo de suelos | E5: 33 | F5: =IFERROR(VLOOKUP(Trabajos!$E5,Clientes,2,FALSE),"") -> Espartina S.A. | G5: El Casalito | H5: 80 | I5: 947.70673 | J5: =IF(H5<>"",H5*I5,"") -> 75816.538 | K5: 1 | L5: =IFERROR(VLOOKUP(K5,Referencias!$H$7:$I$9,2,FALSE),"") -> Tomas | M5: 0 | N5: 576.1 | O5: =IF(M5<>"",M5*N5,"") -> 0 | P5: =IF(J5<>"",J5+O5,"") -> 75816.538 | R5: 0 | S5: 80 | T5: =H5-R5-S5 -> 0
B6: 45909 | C6: 1 | D6: =IFERROR(VLOOKUP(Trabajos!C6,Referencias!$E$7:$F$30,2,FALSE),"") -> Muestreo de suelos | E6: 33 | F6: =IFERROR(VLOOKUP(Trabajos!$E6,Clientes,2,FALSE),"") -> Espartina S.A. | G6: Las Bagualas | H6: 80 | I6: 947.70673 | J6: =IF(H6<>"",H6*I6,"") -> 75816.538 | K6: 1 | L6: =IFERROR(VLOOKUP(K6,Referencias!$H$7:$I$9,2,FALSE),"") -> Tomas | M6: 0 | N6: 576.1 | O6: =IF(M6<>"",M6*N6,"") -> 0 | P6: =IF(J6<>"",J6+O6,"") -> 75816.538 | R6: 0 | S6: 0 | T6: =H6-R6-S6 -> 80
B7: 45909 | C7: 1 | D7: =IFERROR(VLOOKUP(Trabajos!C7,Referencias!$E$7:$F$30,2,FALSE),"") -> Muestreo de suelos | E7: 33 | F7: =IFERROR(VLOOKUP(Trabajos!$E7,Clientes,2,FALSE),"") -> Espartina S.A. | G7: San Marcos | H7: 80 | I7: 947.70673 | J7: =IF(H7<>"",H7*I7,"") -> 75816.538 | K7: 1 | L7: =IFERROR(VLOOKUP(K7,Referencias!$H$7:$I$9,2,FALSE),"") -> Tomas | M7: 0 | N7: 576.1 | O7: =IF(M7<>"",M7*N7,"") -> 0 | P7: =IF(J7<>"",J7+O7,"") -> 75816.538 | R7: 0 | S7: 0 | T7: =H7-R7-S7 -> 80
B8: 45909 | C8: 1 | D8: =IFERROR(VLOOKUP(Trabajos!C8,Referencias!$E$7:$F$30,2,FALSE),"") -> Muestreo de suelos | E8: 33 | F8: =IFERROR(VLOOKUP(Trabajos!$E8,Clientes,2,FALSE),"") -> Espartina S.A. | G8: Los Tulipanes | H8: 80 | I8: 947.70673 | J8: =IF(H8<>"",H8*I8,"") -> 75816.538 | K8: 1 | L8: =IFERROR(VLOOKUP(K8,Referencias!$H$7:$I$9,2,FALSE),"") -> Tomas | M8: 184 | N8: 576.1 | O8: =IF(M8<>"",M8*N8,"") -> 106002.4 | P8: =IF(J8<>"",J8+O8,"") -> 181818.94 | R8: 0 | S8: 0 | T8: =H8-R8-S8 -> 80
B9: 45911 | C9: 1 | D9: =IFERROR(VLOOKUP(Trabajos!C9,Referencias!$E$7:$F$30,2,FALSE),"") -> Muestreo de suelos | E9: 33 | F9: =IFERROR(VLOOKUP(Trabajos!$E9,Clientes,2,FALSE),"") -> Espartina S.A. | G9: La Paz | H9: 80 | I9: 947.70673 | J9: =IF(H9<>"",H9*I9,"") -> 75816.538 | K9: 1 | L9: =IFERROR(VLOOKUP(K9,Referencias!$H$7:$I$9,2,FALSE),"") -> Tomas | M9: 270 | N9: 576.1 | O9: =IF(M9<>"",M9*N9,"") -> 155547 | P9: =IF(J9<>"",J9+O9,"") -> 231363.54 | R9: 0 | S9: 80 | T9: =H9-R9-S9 -> 0
B10: 45911 | C10: 1 | D10: =IFERROR(VLOOKUP(Trabajos!C10,Referencias!$E$7:$F$30,2,FALSE),"") -> Muestreo de suelos | E10: 33 | F10: =IFERROR(VLOOKUP(Trabajos!$E10,Clientes,2,FALSE),"") -> Espartina S.A. | G10: Bella Vista | H10: 80 | I10: 947.70673 | J10: =IF(H10<>"",H10*I10,"") -> 75816.538 | K10: 1 | L10: =IFERROR(VLOOKUP(K10,Referencias!$H$7:$I$9,2,FALSE),"") -> Tomas | M10: 0 | N10: 576.1 | O10: =IF(M10<>"",M10*N10,"") -> 0 | P10: =IF(J10<>"",J10+O10,"") -> 75816.538 | R10: 0 | S10: 0 | T10: =H10-R10-S10 -> 80
B11: 45912 | C11: 10 | D11: =IFERROR(VLOOKUP(Trabajos!C11,Referencias!$E$7:$F$30,2,FALSE),"") -> Mapeo Dron | E11: 122 | F11: =IFERROR(VLOOKUP(Trabajos!$E11,Clientes,2,FALSE),"") -> Martin Juarez | G11: La Juana | H11: 50 | I11: 7625.8 | J11: =IF(H11<>"",H11*I11,"") -> 381290 | K11: 1 | L11: =IFERROR(VLOOKUP(K11,Referencias!$H$7:$I$9,2,FALSE),"") -> Tomas | M11: 0 | N11: 650 | O11: =IF(M11<>"",M11*N11,"") -> 0 | P11: =IF(J11<>"",J11+O11,"") -> 381290 | R11: 0 | S11: 50 | T11: =H11-R11-S11 -> 0
B12: 45913 | C12: 2 | D12: =IFERROR(VLOOKUP(Trabajos!C12,Referencias!$E$7:$F$30,2,FALSE),"") -> Monitoreo de bb y bab | E12: 33 | F12: =IFERROR(VLOOKUP(Trabajos!$E12,Clientes,2,FALSE),"") -> Espartina S.A. | G12: Don Gustavo | H12: 107 | I12: 3318.75 | J12: =IF(H12<>"",H12*I12,"") -> 355106.25 | K12: 1 | L12: =IFERROR(VLOOKUP(K12,Referencias!$H$7:$I$9,2,FALSE),"") -> Tomas | M12: 364 | N12: 576.1 | O12: =IF(M12<>"",M12*N12,"") -> 209700.4 | P12: =IF(J12<>"",J12+O12,"") -> 564806.65 | R12: 0 | S12: 70 | T12: =H12-R12-S12 -> 37
B13: 45913 | C13: 2 | D13: =IFERROR(VLOOKUP(Trabajos!C13,Referencias!$E$7:$F$30,2,FALSE),"") -> Monitoreo de bb y bab | E13: 33 | F13: =IFERROR(VLOOKUP(Trabajos!$E13,Clientes,2,FALSE),"") -> Espartina S.A. | G13: San Luciano | H13: 173 | I13: 3318.75 | J13: =IF(H13<>"",H13*I13,"") -> 574143.75 | K13: 1 | L13: =IFERROR(VLOOKUP(K13,Referencias!$H$7:$I$9,2,FALSE),"") -> Tomas | M13: 340 | N13: 576.1 | O13: =IF(M13<>"",M13*N13,"") -> 195874 | P13: =IF(J13<>"",J13+O13,"") -> 770017.75 | R13: 0 | S13: 0 | T13: =H13-R13-S13 -> 173
B14: 45913 | C14: 1 | D14: =IFERROR(VLOOKUP(Trabajos!C14,Referencias!$E$7:$F$30,2,FALSE),"") -> Muestreo de suelos | E14: 33 | F14: =IFERROR(VLOOKUP(Trabajos!$E14,Clientes,2,FALSE),"") -> Espartina S.A. | G14: Don Gustavo | H14: 80 | I14: 947.70673 | J14: =IF(H14<>"",H14*I14,"") -> 75816.538 | K14: 1 | L14: =IFERROR(VLOOKUP(K14,Referencias!$H$7:$I$9,2,FALSE),"") -> Tomas | M14: 0 | N14: 576.1 | O14: =IF(M14<>"",M14*N14,"") -> 0 | P14: =IF(J14<>"",J14+O14,"") -> 75816.538 | R14: 0 | S14: 0 | T14: =H14-R14-S14 -> 80
B15: 45913 | C15: 1 | D15: =IFERROR(VLOOKUP(Trabajos!C15,Referencias!$E$7:$F$30,2,FALSE),"") -> Muestreo de suelos | E15: 33 | F15: =IFERROR(VLOOKUP(Trabajos!$E15,Clientes,2,FALSE),"") -> Espartina S.A. | G15: San Luciano | H15: 80 | I15: 947.70673 | J15: =IF(H15<>"",H15*I15,"") -> 75816.538 | K15: 1 | L15: =IFERROR(VLOOKUP(K15,Referencias!$H$7:$I$9,2,FALSE),"") -> Tomas | M15: 0 | N15: 576.1 | O15: =IF(M15<>"",M15*N15,"") -> 0 | P15: =IF(J15<>"",J15+O15,"") -> 75816.538 | R15: 0 | S15: 0 | T15: =H15-R15-S15 -> 80
B16: 45914 | C16: 2 | D16: =IFERROR(VLOOKUP(Trabajos!C16,Referencias!$E$7:$F$30,2,FALSE),"") -> Monitoreo de bb y bab | E16: 33 | F16: =IFERROR(VLOOKUP(Trabajos!$E16,Clientes,2,FALSE),"") -> Espartina S.A. | G16: Santa Ana Cobo | H16: 379 | I16: 3318.75 | J16: =IF(H16<>"",H16*I16,"") -> 1257806.2 | K16: 1 | L16: =IFERROR(VLOOKUP(K16,Referencias!$H$7:$I$9,2,FALSE),"") -> Tomas | M16: 172 | N16: 576.1 | O16: =IF(M16<>"",M16*N16,"") -> 99089.2 | P16: =IF(J16<>"",J16+O16,"") -> 1356895.4 | R16: 0 | S16: 95 | T16: =H16-R16-S16 -> 284
... B87: 45940 | C87: 3 | D87: =IFERROR(VLOOKUP(Trabajos!C87,Referencias!$E$7:$F$30,2,FALSE),"") -> Aplicación de cebos | E87: 33 | F87: =IFERROR(VLOOKUP(Trabajos!$E87,Clientes,2,FALSE),"") -> Espartina S.A. | G87: El Moro Viejo | H87: 107 | I87: 7267.5 | J87: =IF(H87<>"",H87*I87,"") -> 777622.5 | K87: 1 | L87: =IFERROR(VLOOKUP(K87,Referencias!$H$7:$I$9,2,FALSE),"") -> Tomas | M87: 156 | N87: 633.85 | O87: =IF(M87<>"",M87*N87,"") -> 98880.6 | P87: =IF(J87<>"",J87+O87,"") -> 876503.1 | R87: 0 | S87: 80 | T87: =H87-R87-S87 -> 27
B88: 45940 | C88: 10 | D88: =IFERROR(VLOOKUP(Trabajos!C88,Referencias!$E$7:$F$30,2,FALSE),"") -> Mapeo Dron | E88: 84 | F88: =IFERROR(VLOOKUP(Trabajos!$E88,Clientes,2,FALSE),"") -> Domingo y Nestor Scioli | G88: La Providencia | H88: 258 | I88: 4360.5 | J88: =IF(H88<>"",H88*I88,"") -> 1125009 | K88: 1 | L88: =IFERROR(VLOOKUP(K88,Referencias!$H$7:$I$9,2,FALSE),"") -> Tomas | M88: 0 | N88: 650 | O88: =IF(M88<>"",M88*N88,"") -> 0 | P88: =IF(J88<>"",J88+O88,"") -> 1125009 | R88: 0 | S88: 80 | T88: 0
B89: 45941 | C89: 2 | D89: =IFERROR(VLOOKUP(Trabajos!C89,Referencias!$E$7:$F$30,2,FALSE),"") -> Monitoreo de bb y bab | E89: 33 | F89: =IFERROR(VLOOKUP(Trabajos!$E89,Clientes,2,FALSE),"") -> Espartina S.A. | G89: Los Tulipanes | H89: 117 | I89: 3035.25 | J89: =IF(H89<>"",H89*I89,"") -> 355124.25 | K89: 3 | L89: =IFERROR(VLOOKUP(K89,Referencias!$H$7:$I$9,2,FALSE),"") -> Zoom | M89: 0 | N89: 588 | O89: =IF(M89<>"",M89*N89,"") -> 0 | P89: =IF(J89<>"",J89+O89,"") -> 355124.25 | R89: 0 | S89: 0 | T89: =H89-R89-S89 -> 117
B90: 45941 | C90: 2 | D90: =IFERROR(VLOOKUP(Trabajos!C90,Referencias!$E$7:$F$30,2,FALSE),"") -> Monitoreo de bb y bab | E90: 33 | F90: =IFERROR(VLOOKUP(Trabajos!$E90,Clientes,2,FALSE),"") -> Espartina S.A. | G90: Las Bagualas | H90: 221 | I90: 3035.25 | J90: =IF(H90<>"",H90*I90,"") -> 670790.25 | K90: 3 | L90: =IFERROR(VLOOKUP(K90,Referencias!$H$7:$I$9,2,FALSE),"") -> Zoom | M90: 176 | N90: 588 | O90: =IF(M90<>"",M90*N90,"") -> 103488 | P90: =IF(J90<>"",J90+O90,"") -> 774278.25 | R90: 0 | S90: 0 | T90: =H90-R90-S90 -> 221
B91: 45941 | C91: 2 | D91: =IFERROR(VLOOKUP(Trabajos!C91,Referencias!$E$7:$F$30,2,FALSE),"") -> Monitoreo de bb y bab | E91: 33 | F91: =IFERROR(VLOOKUP(Trabajos!$E91,Clientes,2,FALSE),"") -> Espartina S.A. | G91: El Casalito | H91: 138 | I91: 3035.25 | J91: =IF(H91<>"",H91*I91,"") -> 418864.5 | K91: 3 | L91: =IFERROR(VLOOKUP(K91,Referencias!$H$7:$I$9,2,FALSE),"") -> Zoom | M91: 152 | N91: 588 | O91: =IF(M91<>"",M91*N91,"") -> 89376 | P91: =IF(J91<>"",J91+O91,"") -> 508240.5 | R91: 0 | S91: 0 | T91: =H91-R91-S91 -> 138
B92: 45941 | C92: 3 | D92: =IFERROR(VLOOKUP(Trabajos!C92,Referencias!$E$7:$F$30,2,FALSE),"") -> Aplicación de cebos | E92: 33 | F92: =IFERROR(VLOOKUP(Trabajos!$E92,Clientes,2,FALSE),"") -> Espartina S.A. | G92: El Moro Viejo | H92: 42 | I92: 7267.5 | J92: =IF(H92<>"",H92*I92,"") -> 305235 | K92: 1 | L92: =IFERROR(VLOOKUP(K92,Referencias!$H$7:$I$9,2,FALSE),"") -> Tomas | M92: 156 | N92: 633.85 | O92: =IF(M92<>"",M92*N92,"") -> 98880.6 | P92: =IF(J92<>"",J92+O92,"") -> 404115.6 | R92: 0 | S92: 0 | T92: =H92-R92-S92 -> 42
B93: 45941 | C93: 3 | D93: =IFERROR(VLOOKUP(Trabajos!C93,Referencias!$E$7:$F$30,2,FALSE),"") -> Aplicación de cebos | E93: 33 | F93: =IFERROR(VLOOKUP(Trabajos!$E93,Clientes,2,FALSE),"") -> Espartina S.A. | G93: San Francisco | H93: 132 | I93: 7267.5 | J93: =IF(H93<>"",H93*I93,"") -> 959310 | K93: 1 | L93: =IFERROR(VLOOKUP(K93,Referencias!$H$7:$I$9,2,FALSE),"") -> Tomas | M93: 90 | N93: 633.85 | O93: =IF(M93<>"",M93*N93,"") -> 57046.5 | P93: =IF(J93<>"",J93+O93,"") -> 1016356.5 | R93: 0 | S93: 80 | T93: =H93-R93-S93 -> 52
B94: 45937 | C94: 1 | D94: =IFERROR(VLOOKUP(Trabajos!C94,Referencias!$E$7:$F$30,2,FALSE),"") -> Muestreo de suelos | E94: 33 | F94: =IFERROR(VLOOKUP(Trabajos!$E94,Clientes,2,FALSE),"") -> Espartina S.A. | G94: San Jose | H94: 80 | I94: 947.70673 | J94: =IF(H94<>"",H94*I94,"") -> 75816.538 | K94: 1 | L94: =IFERROR(VLOOKUP(K94,Referencias!$H$7:$I$9,2,FALSE),"") -> Tomas | M94: 0 | N94: 588 | O94: =IF(M94<>"",M94*N94,"") -> 0 | P94: =IF(J94<>"",J94+O94,"") -> 75816.538 | R94: 0 | S94: 0 | T94: =H94-R94-S94 -> 80
B95: 45944 | C95: 2 | D95: =IFERROR(VLOOKUP(Trabajos!C95,Referencias!$E$7:$F$30,2,FALSE),"") -> Monitoreo de bb y bab | E95: 33 | F95: =IFERROR(VLOOKUP(Trabajos!$E95,Clientes,2,FALSE),"") -> Espartina S.A. | G95: Santa Isabel I | H95: 121 | I95: 3262.5 | J95: =IF(H95<>"",H95*I95,"") -> 394762.5 | K95: 2 | L95: =IFERROR(VLOOKUP(K95,Referencias!$H$7:$I$9,2,FALSE),"") -> Paco | M95: 218 | N95: 633.85 | O95: =IF(M95<>"",M95*N95,"") -> 138179.3 | P95: =IF(J95<>"",J95+O95,"") -> 532941.8 | R95: 70 | S95: 0 | T95: =H95-R95-S95 -> 51
B96: 45944 | C96: 2 | D96: =IFERROR(VLOOKUP(Trabajos!C96,Referencias!$E$7:$F$30,2,FALSE),"") -> Monitoreo de bb y bab | E96: 33 | F96: =IFERROR(VLOOKUP(Trabajos!$E96,Clientes,2,FALSE),"") -> Espartina S.A. | G96: La Susana | H96: 19 | I96: 3262.5 | J96: =IF(H96<>"",H96*I96,"") -> 61987.5 | K96: 2 | L96: =IFERROR(VLOOKUP(K96,Referencias!$H$7:$I$9,2,FALSE),"") -> Paco | M96: 218 | N96: 633.85 | O96: =IF(M96<>"",M96*N96,"") -> 138179.3 | P96: =IF(J96<>"",J96+O96,"") -> 200166.8 | R96: 0 | S96: 0 | T96: =H96-R96-S96 -> 19
B97: 45944 | C97: 10 | D97: =IFERROR(VLOOKUP(Trabajos!C97,Referencias!$E$7:$F$30,2,FALSE),"") -> Mapeo Dron | E97: 84 | F97: =IFERROR(VLOOKUP(Trabajos!$E97,Clientes,2,FALSE),"") -> Domingo y Nestor Scioli | G97: La Providencia | H97: 129 | I97: 4360.5 | J97: =IF(H97<>"",H97*I97,"") -> 562504.5 | K97: 1 | L97: =IFERROR(VLOOKUP(K97,Referencias!$H$7:$I$9,2,FALSE),"") -> Tomas | M97: 0 | N97: 650 | O97: =IF(M97<>"",M97*N97,"") -> 0 | P97: =IF(J97<>"",J97+O97,"") -> 562504.5 | R97: 0 | S97: 80 | T97: 0
B98: 45945 | C98: 2 | D98: =IFERROR(VLOOKUP(Trabajos!C98,Referencias!$E$7:$F$30,2,FALSE),"") -> Monitoreo de bb y bab | E98: 6 | F98: =IFERROR(VLOOKUP(Trabajos!$E98,Clientes,2,FALSE),"") -> La Nany S.A. | G98: La Nany | H98: 242 | I98: 3618.75 | J98: =IF(H98<>"",H98*I98,"") -> 875737.5 | K98: 3 | L98: =IFERROR(VLOOKUP(K98,Referencias!$H$7:$I$9,2,FALSE),"") -> Zoom | M98: 0 | N98: 650 | O98: =IF(M98<>"",M98*N98,"") -> 0 | P98: =IF(J98<>"",J98+O98,"") -> 875737.5 | R98: 0 | S98: 0 | T98: =H98-R98-S98 -> 242
B99: 45945 | C99: 2 | D99: =IFERROR(VLOOKUP(Trabajos!C99,Referencias!$E$7:$F$30,2,FALSE),"") -> Monitoreo de bb y bab | E99: 6 | F99: =IFERROR(VLOOKUP(Trabajos!$E99,Clientes,2,FALSE),"") -> La Nany S.A. | G99: La Adelia | H99: 260 | I99: 3618.75 | J99: =IF(H99<>"",H99*I99,"") -> 940875 | K99: 3 | L99: =IFERROR(VLOOKUP(K99,Referencias!$H$7:$I$9,2,FALSE),"") -> Zoom | M99: 104 | N99: 650 | O99: =IF(M99<>"",M99*N99,"") -> 67600 | P99: =IF(J99<>"",J99+O99,"") -> 1008475 | R99: 0 | S99: 0 | T99: =H99-R99-S99 -> 260
B100: 45945 | C100: 3 | D100: =IFERROR(VLOOKUP(Trabajos!C100,Referencias!$E$7:$F$30,2,FALSE),"") -> Aplicación de cebos | E100: 33 | F100: =IFERROR(VLOOKUP(Trabajos!$E100,Clientes,2,FALSE),"") -> Espartina S.A. | G100: Santa Isabel Cozumel | H100: 115 | I100: 7250 | J100: =IF(H100<>"",H100*I100,"") -> 833750 | K100: 2 | L100: =IFERROR(VLOOKUP(K100,Referencias!$H$7:$I$9,2,FALSE),"") -> Paco | M100: 186 | N100: 633.85 | O100: =IF(M100<>"",M100*N100,"") -> 117896.1 | P100: =IF(J100<>"",J100+O100,"") -> 951646.1 | R100: 80 | S100: 0 | T100: =H100-R100-S100 -> 35
B101: 45945 | C101: 3 | D101: =IFERROR(VLOOKUP(Trabajos!C101,Referencias!$E$7:$F$30,2,FALSE),"") -> Aplicación de cebos | E101: 33 | F101: =IFERROR(VLOOKUP(Trabajos!$E101,Clientes,2,FALSE),"") -> Espartina S.A. | G101: San Francisco | H101: 132 | I101: 7267.5 | J101: =IF(H101<>"",H101*I101,"") -> 959310 | K101: 1 | L101: =IFERROR(VLOOKUP(K101,Referencias!$H$7:$I$9,2,FALSE),"") -> Tomas | M101: 90 | N101: 633.85 | O101: =IF(M101<>"",M101*N101,"") -> 57046.5 | P101: =IF(J101<>"",J101+O101,"") -> 1016356.5 | R101: 0 | S101: 80 | T101: =H101-R101-S101 -> 52
B102: 45945 | C102: 3 | D102: =IFERROR(VLOOKUP(Trabajos!C102,Referencias!$E$7:$F$30,2,FALSE),"") -> Aplicación de cebos | E102: 33 | F102: =IFERROR(VLOOKUP(Trabajos!$E102,Clientes,2,FALSE),"") -> Espartina S.A. | G102: Don Gustavo | H102: 77 | I102: 7267.5 | J102: =IF(H102<>"",H102*I102,"") -> 559597.5 | K102: 3 | L102: =IFERROR(VLOOKUP(K102,Referencias!$H$7:$I$9,2,FALSE),"") -> Zoom | M102: 185 | N102: 633.85 | O102: =IF(M102<>"",M102*N102,"") -> 117262.25 | P102: =IF(J102<>"",J102+O102,"") -> 676859.75 | R102: 0 | S102: 0 | T102: =H102-R102-S102 -> 77
B103: 45945 | C103: 3 | D103: =IFERROR(VLOOKUP(Trabajos!C103,Referencias!$E$7:$F$30,2,FALSE),"") -> Aplicación de cebos | E103: 33 | F103: =IFERROR(VLOOKUP(Trabajos!$E103,Clientes,2,FALSE),"") -> Espartina S.A. | G103: Macedo | H103: 36 | I103: 7267.5 | J103: =IF(H103<>"",H103*I103,"") -> 261630 | K103: 3 | L103: =IFERROR(VLOOKUP(K103,Referencias!$H$7:$I$9,2,FALSE),"") -> Zoom | M103: 185 | N103: 633.85 | O103: =IF(M103<>"",M103*N103,"") -> 117262.25 | P103: =IF(J103<>"",J103+O103,"") -> 378892.25 | R103: 0 | S103: 0 | T103: =H103-R103-S103 -> 36
B104: 45941 | C104: 3 | D104: =IFERROR(VLOOKUP(Trabajos!C104,Referencias!$E$7:$F$30,2,FALSE),"") -> Aplicación de cebos | E104: 4 | F104: =IFERROR(VLOOKUP(Trabajos!$E104,Clientes,2,FALSE),"") -> Purtierra | G104: Ojo de Agua | H104: 122 | I104: 7460 | J104: =IF(H104<>"",H104*I104,"") -> 910120 | K104: 3 | L104: =IFERROR(VLOOKUP(K104,Referencias!$H$7:$I$9,2,FALSE),"") -> Zoom | M104: 92 | N104: 650 | O104: =IF(M104<>"",M104*N104,"") -> 59800 | P104: =IF(J104<>"",J104+O104,"") -> 969920 | R104: 0 | S104: 0 | T104: =H104-R104-S104 -> 122
B105: 45946 | C105: 1 | D105: =IFERROR(VLOOKUP(Trabajos!C105,Referencias!$E$7:$F$30,2,FALSE),"") -> Muestreo de suelos | E105: 33 | F105: =IFERROR(VLOOKUP(Trabajos!$E105,Clientes,2,FALSE),"") -> Espartina S.A. | G105: San Marcos | H105: 80 | I105: 947.70673 | J105: =IF(H105<>"",H105*I105,"") -> 75816.538 | K105: 3 | L105: =IFERROR(VLOOKUP(K105,Referencias!$H$7:$I$9,2,FALSE),"") -> Zoom | M105: 0 | N105: 588 | O105: =IF(M105<>"",M105*N105,"") -> 0 | P105: =IF(J105<>"",J105+O105,"") -> 75816.538 | R105: 0 | S105: 0 | T105: =H105-R105-S105 -> 80
B106: 45946 | C106: 1 | D106: =IFERROR(VLOOKUP(Trabajos!C106,Referencias!$E$7:$F$30,2,FALSE),"") -> Muestreo de suelos | E106: 33 | F106: =IFERROR(VLOOKUP(Trabajos!$E106,Clientes,2,FALSE),"") -> Espartina S.A. | G106: El Casalito | H106: 80 | I106: 947.70673 | J106: =IF(H106<>"",H106*I106,"") -> 75816.538 | K106: 3 | L106: =IFERROR(VLOOKUP(K106,Referencias!$H$7:$I$9,2,FALSE),"") -> Zoom | M106: 0 | N106: 588 | O106: =IF(M106<>"",M106*N106,"") -> 0 | P106: =IF(J106<>"",J106+O106,"") -> 75816.538 | R106: 0 | S106: 0 | T106: =H106-R106-S106 -> 80
B107: 45946 | C107: 1 | D107: =IFERROR(VLOOKUP(Trabajos!C107,Referencias!$E$7:$F$30,2,FALSE),"") -> Muestreo de suelos | E107: 33 | F107: =IFERROR(VLOOKUP(Trabajos!$E107,Clientes,2,FALSE),"") -> Espartina S.A. | G107: Aitona | H107: 80 | I107: 947.70673 | J107: =IF(H107<>"",H107*I107,"") -> 75816.538 | K107: 3 | L107: =IFERROR(VLOOKUP(K107,Referencias!$H$7:$I$9,2,FALSE),"") -> Zoom | M107: 0 | N107: 588 | O107: =IF(M107<>"",M107*N107,"") -> 0 | P107: =IF(J107<>"",J107+O107,"") -> 75816.538 | R107: 0 | S107: 0 | T107: =H107-R107-S107 -> 80
B108: 45946 | C108: 1 | D108: =IFERROR(VLOOKUP(Trabajos!C108,Referencias!$E$7:$F$30,2,FALSE),"") -> Muestreo de suelos | E108: 33 | F108: =IFERROR(VLOOKUP(Trabajos!$E108,Clientes,2,FALSE),"") -> Espartina S.A. | G108: Los Tulipanes | H108: 80 | I108: 947.70673 | J108: =IF(H108<>"",H108*I108,"") -> 75816.538 | K108: 3 | L108: =IFERROR(VLOOKUP(K108,Referencias!$H$7:$I$9,2,FALSE),"") -> Zoom | M108: 0 | N108: 588 | O108: =IF(M108<>"",M108*N108,"") -> 0 | P108: =IF(J108<>"",J108+O108,"") -> 75816.538 | R108: 0 | S108: 0 | T108: =H108-R108-S108 -> 80
B109: 45946 | C109: 2 | D109: =IFERROR(VLOOKUP(Trabajos!C109,Referencias!$E$7:$F$30,2,FALSE),"") -> Monitoreo de bb y bab | E109: 33 | F109: =IFERROR(VLOOKUP(Trabajos!$E109,Clientes,2,FALSE),"") -> Espartina S.A. | G109: El Montiel | H109: 276 | I109: 3262.5 | J109: =IF(H109<>"",H109*I109,"") -> 900450 | K109: 3 | L109: =IFERROR(VLOOKUP(K109,Referencias!$H$7:$I$9,2,FALSE),"") -> Zoom | M109: 398 | N109: 633.85 | O109: =IF(M109<>"",M109*N109,"") -> 252272.3 | P109: =IF(J109<>"",J109+O109,"") -> 1152722.3 | R109: 0 | S109: 0 | T109: =H109-R109-S109 -> 276
... B219: 45969 | C219: 3 | D219: =IFERROR(VLOOKUP(Trabajos!C219,Referencias!$E$7:$F$30,2,FALSE),"") -> Aplicación de cebos | E219: 72 | F219: =IFERROR(VLOOKUP(Trabajos!$E219,Clientes,2,FALSE),"") -> La Mylucha | G219: La Mylucha | H219: 54 | I219: 0 | J219: =IF(H219<>"",H219*I219,"") -> 0 | K219: 3 | L219: =IFERROR(VLOOKUP(K219,Referencias!$H$7:$I$9,2,FALSE),"") -> Zoom | M219: 40 | N219: 0 | O219: =IF(M219<>"",M219*N219,"") -> 0 | P219: =IF(J219<>"",J219+O219,"") -> 0 | R219: 0 | S219: 0 | T219: =H219-R219-S219 -> 54
B220: 45969 | C220: 2 | D220: =IFERROR(VLOOKUP(Trabajos!C220,Referencias!$E$7:$F$30,2,FALSE),"") -> Monitoreo de bb y bab | E220: 84 | F220: =IFERROR(VLOOKUP(Trabajos!$E220,Clientes,2,FALSE),"") -> Domingo y Nestor Scioli | G220: Gugliota | H220: 139 | I220: 3633.75 | J220: =IF(H220<>"",H220*I220,"") -> 505091.25 | K220: 3 | L220: =IFERROR(VLOOKUP(K220,Referencias!$H$7:$I$9,2,FALSE),"") -> Zoom | M220: 50 | N220: 650 | O220: =IF(M220<>"",M220*N220,"") -> 32500 | P220: =IF(J220<>"",J220+O220,"") -> 537591.25 | R220: 0 | S220: 0 | T220: 0
...

Sheet Trabajos 2
B2: Trabajos
G3: Total | H3: =SUBTOTAL(9,H5:H156) -> 80.3 | O3: Total | P3: =SUBTOTAL(9,P5:P156) -> 26437243
B4: Fecha | C4: Cod. Trabajo | D4: Tipo de trabajo | E4: Cod. Cliente | F4: Cliente | G4: Establecimiento | H4: Dia | I4: $/dia | J4: Subtotal | K4: Cod. Vehiculo | L4: Vehiculo | M4: Distancia | N4: $/Km | O4: Movilidad | P4: Importe | R4: Paco | S4: Tomas | T4: Zoom
B5: 45908 | C5: 4 | D5: =IFERROR(VLOOKUP(C5,Referencias!$E$7:$F$30,2,FALSE),"") -> Seguimiento de cultivos | E5: 11 | F5: =IFERROR(VLOOKUP(E5,Clientes,2,FALSE),"") -> Carlos Fernando Fuertes | G5: La Tolderia | H5: 0.5 | I5: 200000 | J5: =IF(H5<>"",H5*I5,"") -> 100000 | K5: 1 | L5: =IFERROR(VLOOKUP(K5,Referencias!$H$7:$I$9,2,FALSE),"") -> Tomas | M5: 120 | N5: 650 | O5: =IF(M5<>"",M5*N5,"") -> 78000 | P5: =IF(J5<>"",J5+O5,"") -> 178000 | R5: 0 | S5: 0.5 | T5: =H5-R5-S5 -> 0
B6: 45912 | C6: 4 | D6: =IFERROR(VLOOKUP(C6,Referencias!$E$7:$F$30,2,FALSE),"") -> Seguimiento de cultivos | E6: 107 | F6: =IFERROR(VLOOKUP(E6,Clientes,2,FALSE),"") -> Omar Piaggio | G6: Costa del Moro | H6: 1 | I6: 150000 | J6: =IF(H6<>"",H6*I6,"") -> 150000 | K6: 1 | L6: =IFERROR(VLOOKUP(K6,Referencias!$H$7:$I$9,2,FALSE),"") -> Tomas | M6: 225 | N6: 650 | O6: =IF(M6<>"",M6*N6,"") -> 146250 | P6: =IF(J6<>"",J6+O6,"") -> 296250 | R6: 0 | S6: 1 | T6: =H6-R6-S6 -> 0
B7: 45917 | C7: 4 | D7: =IFERROR(VLOOKUP(C7,Referencias!$E$7:$F$30,2,FALSE),"") -> Seguimiento de cultivos | E7: 107 | F7: =IFERROR(VLOOKUP(E7,Clientes,2,FALSE),"") -> Omar Piaggio | G7: Costa del Moro | H7: 0 | I7: 150000 | J7: =IF(H7<>"",H7*I7,"") -> 0 | K7: 1 | L7: =IFERROR(VLOOKUP(K7,Referencias!$H$7:$I$9,2,FALSE),"") -> Tomas | M7: 225 | N7: 650 | O7: =IF(M7<>"",M7*N7,"") -> 146250 | P7: =IF(J7<>"",J7+O7,"") -> 146250 | R7: 0 | S7: 0 | T7: =H7-R7-S7 -> 0
B8: 45926 | C8: 4 | D8: =IFERROR(VLOOKUP(C8,Referencias!$E$7:$F$30,2,FALSE),"") -> Seguimiento de cultivos | E8: 24 | F8: =IFERROR(VLOOKUP(E8,Clientes,2,FALSE),"") -> Nugas S.A. | G8: La Alborada | H8: 0.5 | I8: 200000 | J8: =IF(H8<>"",H8*I8,"") -> 100000 | K8: 1 | L8: =IFERROR(VLOOKUP(K8,Referencias!$H$7:$I$9,2,FALSE),"") -> Tomas | M8: 160 | N8: 650 | O8: =IF(M8<>"",M8*N8,"") -> 104000 | P8: =IF(J8<>"",J8+O8,"") -> 204000 | R8: 0 | S8: 0.5 | T8: =H8-R8-S8 -> 0
B9: 45933 | C9: 4 | D9: =IFERROR(VLOOKUP(C9,Referencias!$E$7:$F$30,2,FALSE),"") -> Seguimiento de cultivos | E9: 24 | F9: =IFERROR(VLOOKUP(E9,Clientes,2,FALSE),"") -> Nugas S.A. | G9: La Alborada | H9: 0.5 | I9: 200000 | J9: =IF(H9<>"",H9*I9,"") -> 100000 | K9: 3 | L9: =IFERROR(VLOOKUP(K9,Referencias!$H$7:$I$9,2,FALSE),"") -> Zoom | M9: 160 | N9: 650 | O9: =IF(M9<>"",M9*N9,"") -> 104000 | P9: =IF(J9<>"",J9+O9,"") -> 204000 | R9: 0 | S9: 0 | T9: =H9-R9-S9 -> 0.5
B10: 45934 | C10: 4 | D10: =IFERROR(VLOOKUP(C10,Referencias!$E$7:$F$30,2,FALSE),"") -> Seguimiento de cultivos | E10: 107 | F10: =IFERROR(VLOOKUP(E10,Clientes,2,FALSE),"") -> Omar Piaggio | G10: Costa del Moro | H10: 1 | I10: 150000 | J10: =IF(H10<>"",H10*I10,"") -> 150000 | K10: 1 | L10: =IFERROR(VLOOKUP(K10,Referencias!$H$7:$I$9,2,FALSE),"") -> Tomas | M10: 225 | N10: 650 | O10: =IF(M10<>"",M10*N10,"") -> 146250 | P10: =IF(J10<>"",J10+O10,"") -> 296250 | R10: 0 | S10: 1 | T10: =H10-R10-S10 -> 0
B11: 45939 | C11: 4 | D11: =IFERROR(VLOOKUP(C11,Referencias!$E$7:$F$30,2,FALSE),"") -> Seguimiento de cultivos | E11: 11 | F11: =IFERROR(VLOOKUP(E11,Clientes,2,FALSE),"") -> Carlos Fernando Fuertes | G11: La Tolderia | H11: 0.5 | I11: 200000 | J11: =IF(H11<>"",H11*I11,"") -> 100000 | K11: 1 | L11: =IFERROR(VLOOKUP(K11,Referencias!$H$7:$I$9,2,FALSE),"") -> Tomas | M11: 120 | N11: 650 | O11: =IF(M11<>"",M11*N11,"") -> 78000 | P11: =IF(J11<>"",J11+O11,"") -> 178000 | R11: 0 | S11: 0.5 | T11: =H11-R11-S11 -> 0
B12: 45940 | C12: 4 | D12: =IFERROR(VLOOKUP(C12,Referencias!$E$7:$F$30,2,FALSE),"") -> Seguimiento de cultivos | E12: 24 | F12: =IFERROR(VLOOKUP(E12,Clientes,2,FALSE),"") -> Nugas S.A. | G12: La Alborada | H12: 0.5 | I12: 200000 | J12: =IF(H12<>"",H12*I12,"") -> 100000 | K12: 3 | L12: =IFERROR(VLOOKUP(K12,Referencias!$H$7:$I$9,2,FALSE),"") -> Zoom | M12: 160 | N12: 650 | O12: =IF(M12<>"",M12*N12,"") -> 104000 | P12: =IF(J12<>"",J12+O12,"") -> 204000 | R12: 0 | S12: 0 | T12: =H12-R12-S12 -> 0.5
B13: 45948 | C13: 4 | D13: =IFERROR(VLOOKUP(C13,Referencias!$E$7:$F$30,2,FALSE),"") -> Seguimiento de cultivos | E13: 107 | F13: =IFERROR(VLOOKUP(E13,Clientes,2,FALSE),"") -> Omar Piaggio | G13: Costa del Moro | H13: 1 | I13: 150000 | J13: =IF(H13<>"",H13*I13,"") -> 150000 | K13: 1 | L13: =IFERROR(VLOOKUP(K13,Referencias!$H$7:$I$9,2,FALSE),"") -> Tomas | M13: 225 | N13: 650 | O13: =IF(M13<>"",M13*N13,"") -> 146250 | P13: =IF(J13<>"",J13+O13,"") -> 296250 | R13: 0 | S13: 1 | T13: =H13-R13-S13 -> 0
B14: 45950 | C14: 4 | D14: =IFERROR(VLOOKUP(C14,Referencias!$E$7:$F$30,2,FALSE),"") -> Seguimiento de cultivos | E14: 107 | F14: =IFERROR(VLOOKUP(E14,Clientes,2,FALSE),"") -> Omar Piaggio | G14: Costa del Moro | H14: 1 | I14: 150000 | J14: =IF(H14<>"",H14*I14,"") -> 150000 | K14: 1 | L14: =IFERROR(VLOOKUP(K14,Referencias!$H$7:$I$9,2,FALSE),"") -> Tomas | M14: 225 | N14: 650 | O14: =IF(M14<>"",M14*N14,"") -> 146250 | P14: =IF(J14<>"",J14+O14,"") -> 296250 | R14: 0 | S14: 1 | T14: =H14-R14-S14 -> 0
B15: 45950 | C15: 4 | D15: =IFERROR(VLOOKUP(C15,Referencias!$E$7:$F$30,2,FALSE),"") -> Seguimiento de cultivos | E15: 24 | F15: =IFERROR(VLOOKUP(E15,Clientes,2,FALSE),"") -> Nugas S.A. | G15: La Alborada | H15: 0.5 | I15: 200000 | J15: =IF(H15<>"",H15*I15,"") -> 100000 | K15: 3 | L15: =IFERROR(VLOOKUP(K15,Referencias!$H$7:$I$9,2,FALSE),"") -> Zoom | M15: 160 | N15: 650 | O15: =IF(M15<>"",M15*N15,"") -> 104000 | P15: =IF(J15<>"",J15+O15,"") -> 204000 | R15: 0 | S15: 0 | T15: =H15-R15-S15 -> 0.5
B16: 45959 | C16: 4 | D16: =IFERROR(VLOOKUP(C16,Referencias!$E$7:$F$30,2,FALSE),"") -> Seguimiento de cultivos | E16: 24 | F16: =IFERROR(VLOOKUP(E16,Clientes,2,FALSE),"") -> Nugas S.A. | G16: La Alborada | H16: 0.5 | I16: 200000 | J16: =IF(H16<>"",H16*I16,"") -> 100000 | K16: 3 | L16: =IFERROR(VLOOKUP(K16,Referencias!$H$7:$I$9,2,FALSE),"") -> Zoom | M16: 160 | N16: 650 | O16: =IF(M16<>"",M16*N16,"") -> 104000 | P16: =IF(J16<>"",J16+O16,"") -> 204000 | R16: 0 | S16: 0 | T16: =H16-R16-S16 -> 0.5
... B99: 46219 | C99: 4 | D99: =IFERROR(VLOOKUP(C99,Referencias!$E$7:$F$30,2,FALSE),"") -> Seguimiento de cultivos | E99: 107 | F99: =IFERROR(VLOOKUP(E99,Clientes,2,FALSE),"") -> Omar Piaggio | G99: Costa del Moro | H99: 1 | I99: 150000 | J99: =IF(H99<>"",H99*I99,"") -> 150000 | K99: 1 | L99: =IFERROR(VLOOKUP(K99,Referencias!$H$7:$I$9,2,FALSE),"") -> Tomas | M99: 225 | N99: 850 | O99: =IF(M99<>"",M99*N99,"") -> 191250 | P99: =IF(J99<>"",J99+O99,"") -> 341250 | R99: 0 | S99: 1 | T99: =H99-R99-S99 -> 0
D100: =IFERROR(VLOOKUP(C100,Referencias!$E$7:$F$30,2,FALSE),"") | F100: =IFERROR(VLOOKUP(E100,Clientes,2,FALSE),"") | J100: =IF(H100<>"",H100*I100,"") | L100: =IFERROR(VLOOKUP(K100,Referencias!$H$7:$I$9,2,FALSE),"") | O100: =IF(M100<>"",M100*N100,"") | P100: =IF(J100<>"",J100+O100,"")
D101: =IFERROR(VLOOKUP(C101,Referencias!$E$7:$F$30,2,FALSE),"") | F101: =IFERROR(VLOOKUP(E101,Clientes,2,FALSE),"") | J101: =IF(H101<>"",H101*I101,"") | L101: =IFERROR(VLOOKUP(K101,Referencias!$H$7:$I$9,2,FALSE),"") | O101: =IF(M101<>"",M101*N101,"") | P101: =IF(J101<>"",J101+O101,"")
D102: =IFERROR(VLOOKUP(C102,Referencias!$E$7:$F$30,2,FALSE),"") | F102: =IFERROR(VLOOKUP(E102,Clientes,2,FALSE),"") | J102: =IF(H102<>"",H102*I102,"") | L102: =IFERROR(VLOOKUP(K102,Referencias!$H$7:$I$9,2,FALSE),"") | O102: =IF(M102<>"",M102*N102,"") | P102: =IF(J102<>"",J102+O102,"")
D103: =IFERROR(VLOOKUP(C103,Referencias!$E$7:$F$30,2,FALSE),"") | F103: =IFERROR(VLOOKUP(E103,Clientes,2,FALSE),"") | J103: =IF(H103<>"",H103*I103,"") | L103: =IFERROR(VLOOKUP(K103,Referencias!$H$7:$I$9,2,FALSE),"") | O103: =IF(M103<>"",M103*N103,"") | P103: =IF(J103<>"",J103+O103,"")
D104: =IFERROR(VLOOKUP(C104,Referencias!$E$7:$F$30,2,FALSE),"") | F104: =IFERROR(VLOOKUP(E104,Clientes,2,FALSE),"") | J104: =IF(H104<>"",H104*I104,"") | L104: =IFERROR(VLOOKUP(K104,Referencias!$H$7:$I$9,2,FALSE),"") | O104: =IF(M104<>"",M104*N104,"") | P104: =IF(J104<>"",J104+O104,"")
D105: =IFERROR(VLOOKUP(C105,Referencias!$E$7:$F$30,2,FALSE),"") | F105: =IFERROR(VLOOKUP(E105,Clientes,2,FALSE),"") | J105: =IF(H105<>"",H105*I105,"") | L105: =IFERROR(VLOOKUP(K105,Referencias!$H$7:$I$9,2,FALSE),"") | O105: =IF(M105<>"",M105*N105,"") | P105: =IF(J105<>"",J105+O105,"")
D106: =IFERROR(VLOOKUP(C106,Referencias!$E$7:$F$30,2,FALSE),"") | F106: =IFERROR(VLOOKUP(E106,Clientes,2,FALSE),"") | J106: =IF(H106<>"",H106*I106,"") | L106: =IFERROR(VLOOKUP(K106,Referencias!$H$7:$I$9,2,FALSE),"") | O106: =IF(M106<>"",M106*N106,"") | P106: =IF(J106<>"",J106+O106,"")
D107: =IFERROR(VLOOKUP(C107,Referencias!$E$7:$F$30,2,FALSE),"") | F107: =IFERROR(VLOOKUP(E107,Clientes,2,FALSE),"") | J107: =IF(H107<>"",H107*I107,"") | L107: =IFERROR(VLOOKUP(K107,Referencias!$H$7:$I$9,2,FALSE),"") | O107: =IF(M107<>"",M107*N107,"") | P107: =IF(J107<>"",J107+O107,"")
D108: =IFERROR(VLOOKUP(C108,Referencias!$E$7:$F$30,2,FALSE),"") | F108: =IFERROR(VLOOKUP(E108,Clientes,2,FALSE),"") | J108: =IF(H108<>"",H108*I108,"") | L108: =IFERROR(VLOOKUP(K108,Referencias!$H$7:$I$9,2,FALSE),"") | O108: =IF(M108<>"",M108*N108,"") | P108: =IF(J108<>"",J108+O108,"")
D109: =IFERROR(VLOOKUP(C109,Referencias!$E$7:$F$30,2,FALSE),"") | F109: =IFERROR(VLOOKUP(E109,Clientes,2,FALSE),"") | J109: =IF(H109<>"",H109*I109,"") | L109: =IFERROR(VLOOKUP(K109,Referencias!$H$7:$I$9,2,FALSE),"") | O109: =IF(M109<>"",M109*N109,"") | P109: =IF(J109<>"",J109+O109,"")
D110: =IFERROR(VLOOKUP(C110,Referencias!$E$7:$F$30,2,FALSE),"") | F110: =IFERROR(VLOOKUP(E110,Clientes,2,FALSE),"") | J110: =IF(H110<>"",H110*I110,"") | L110: =IFERROR(VLOOKUP(K110,Referencias!$H$7:$I$9,2,FALSE),"") | O110: =IF(M110<>"",M110*N110,"") | P110: =IF(J110<>"",J110+O110,"")
D111: =IFERROR(VLOOKUP(C111,Referencias!$E$7:$F$30,2,FALSE),"") | F111: =IFERROR(VLOOKUP(E111,Clientes,2,FALSE),"") | J111: =IF(H111<>"",H111*I111,"") | L111: =IFERROR(VLOOKUP(K111,Referencias!$H$7:$I$9,2,FALSE),"") | O111: =IF(M111<>"",M111*N111,"") | P111: =IF(J111<>"",J111+O111,"")
... D156: =IFERROR(VLOOKUP(C156,Referencias!$E$7:$F$30,2,FALSE),"") | F156: =IFERROR(VLOOKUP(E156,Clientes,2,FALSE),"") | J156: =IF(H156<>"",H156*I156,"") | L156: =IFERROR(VLOOKUP(K156,Referencias!$H$7:$I$9,2,FALSE),"") | O156: =IF(M156<>"",M156*N156,"") | P156: =IF(J156<>"",J156+O156,"")
B157: Total | H157: =SUM(H5:H156) -> 80.3 | J157: =SUM(J5:J156) -> 12789680 | O157: =SUM(O5:O156) -> 13647563 | P157: =SUM(P5:P156) -> 26437243 | R157: =SUM(R5:R156) -> 0 | S157: =SUM(S5:S156) -> 47 | T157: =SUM(T5:T156) -> 33.3

Sheet Viajes
B2: Viajes
K3: Suma de km recorridos | O3: Saldo en km | S3: Saldo en $
J4: Periodo | K4: Tomas | L4: Paco | N4: Periodo | O4: Tomas | P4: Paco | R4: Periodo | S4: Tomas | T4: Paco
B5: Fecha | C5: Cliente-Establecimiento | D5: Auto | E5: Km recorridos | F5: Km cobrados | G5: Km cobr. correg. | H5: Diferencia | J5: 1-09 al 31-08 | K5: =SUMIF(D6:D309,K4,E6:E309) -> 33904 | L5: =SUMIF(D6:D309,L4,E6:E309) -> 21297 | N5: 1-09 al 31-08 | O5: =SUMIF(D6:D309,O4,H6:H309) -> -10289.156 | P5: =SUMIF(D6:D309,P4,H6:H309) -> -9288.0119 | R5: 1-09 al 31-08 | S5: =-(O5*650) -> 6687951.2 | T5: =-(P5*650) -> 6037207.7
B6: 45908 | C6: La Tolderia | D6: Tomas | E6: 152 | F6: 120 | G6: 120 | H6: =G6-E6 -> -32
B7: 45909 | C7: Cobo Espartina | D7: Tomas | E7: 129 | F7: 184 | G7: =F7*0.88630769 -> 163.08061 | H7: =G7-E7 -> 34.080615
B8: 45910 | C8: Escuri | D8: Paco | E8: 100 | F8: 0 | G8: 0 | H8: =G8-E8 -> -100
B9: 45911 | C9: La Paz-Bella Vista | D9: Tomas | E9: 290 | F9: 270 | G9: =F9*0.88630769 -> 239.30308 | H9: =G9-E9 -> -50.696924
B10: 45912 | C10: La Juana-Costa del Moro | D10: Tomas | E10: 281 | F10: 92 | G10: 92 | H10: =G10-E10 -> -189
B11: 45913 | C11: San Luciano-Don Gustavo | D11: Tomas | E11: 378 | F11: 704 | G11: =F11*0.88630769 -> 623.96061 | H11: =G11-E11 -> 245.96061
B12: 45914 | C12: Santa Ana Cobo | D12: Tomas | E12: 133 | F12: 172 | G12: =F12*0.88630769 -> 152.44492 | H12: =G12-E12 -> 19.444923
B13: 45915 | C13: Macedo | D13: Tomas | E13: 352 | F13: 328 | G13: =F13*0.88630769 -> 290.70892 | H13: =G13-E13 -> -61.291078
B14: 45916 | C14: La Florida | D14: Tomas | E14: 313 | F14: 370 | G14: =F14*0.88630769 -> 327.93385 | H14: =G14-E14 -> 14.933845
B15: 45916 | C15: El Basural | D15: Paco | E15: 295 | F15: 212 | G15: =F15*0.88630769 -> 187.89723 | H15: =G15-E15 -> -107.10277
B16: 45917 | C16: San Narciso | D16: Tomas | E16: 134 | F16: 208 | G16: =F16*0.904615 -> 188.15992 | H16: =G16-E16 -> 54.15992
B17: 45917 | C17: Costa del Moro | D17: Tomas | E17: 133 | F17: 92 | G17: 92 | H17: =G17-E17 -> -41
B18: 45917 | C18: La Cachila-Doña Hilda | D18: Paco | E18: 302 | F18: 230 | G18: =F18*0.88630769 -> 203.85077 | H18: =G18-E18 -> -98.149231
B19: 45918 | C19: San Francisco-Santa Barbara | D19: Tomas | E19: 195 | F19: 90 | G19: =F19*0.88630769 -> 79.767692 | H19: =G19-E19 -> -115.23231
B20: 45918 | C20: Follaneras-San Lorenzo | D20: Paco | E20: 339 | F20: 180 | G20: =F20*0.88630769 -> 159.53538 | H20: =G20-E20 -> -179.46462
B21: 45922 | C21: Tandil Ranger | D21: Paco | E21: 1089 | F21: 1089 | G21: =F21*0.88630769 -> 965.18907 | H21: =G21-E21 -> -123.81093
B22: 45922 | C22: Tandil Strada | D22: Paco | E22: 952 | F22: 499 | G22: =F22*0.88630769 -> 442.26754 | H22: =G22-E22 -> -509.73246
B23: 45923 | C23: Santa Maria del Moro-San Narciso | D23: Tomas | E23: 255 | F23: 206 | G23: =F23*0.904615 -> 186.35069 | H23: =G23-E23 -> -68.64931
B24: 45924 | C24: San Narciso-Las Overas | D24: Tomas | E24: 275 | F24: 208 | G24: =F24*0.904615 -> 188.15992 | H24: =G24-E24 -> -86.84008
B25: 45925 | C25: La Baguala-La Juanita | D25: Tomas | E25: 239 | F25: 156 | G25: =F25*0.904615 -> 141.11994 | H25: =G25-E25 -> -97.88006
B26: 45926 | C26: La Alborada | D26: Tomas | E26: 236 | F26: 160 | G26: 160 | H26: =G26-E26 -> -76
B27: 45929 | C27: Tres Marias | D27: Paco | E27: 1391 | F27: 210 | G27: =F27*0.904615384615384 -> 189.96923 | H27: =G27-E27 -> -1201.0308
B28: 45929 | C28: Santa Marta | D28: Tomas | E28: 151 | F28: 50 | G28: 50 | H28: =G28-E28 -> -101
B29: 45930 | C29: Tres Marias-Santa Isabel Cozumel | D29: Paco | E29: 0 | F29: 186 | G29: =F29*0.904615384615384 -> 168.25846 | H29: =G29-E29 -> 168.25846
B30: 45930 | C30: Santa Marta | D30: Tomas | E30: 121 | F30: 50 | G30: 50 | H30: =G30-E30 -> -71
B31: 45931 | C31: Cerro Guacho | D31: Paco | E31: 0 | F31: 262 | G31: 262 | H31: =G31-E31 -> 262
B32: 45932 | C32: La Azucena | D32: Paco | E32: 0 | F32: 274 | G32: =F32*0.904615384615384 -> 247.86462 | H32: =G32-E32 -> 247.86462
B33: 45932 | C33: El Moro Viejo | D33: Tomas | E33: 201 | F33: 156 | G33: =F33*0.904615384615384 -> 141.12 | H33: =G33-E33 -> -59.88
B34: 45933 | C34: La Azucena | D34: Paco | E34: 0 | F34: 0 | G34: 0 | H34: =G34-E34 -> 0
B35: 45933 | C35: El Moro Viejo-La Guadalupe | D35: Tomas | E35: 228 | F35: 220 | G35: 220 | H35: =G35-E35 -> -8
B36: 45934 | C36: Santa Isabel Cozumel | D36: Paco | E36: 0 | F36: 0 | G36: 0 | H36: =G36-E36 -> 0
B37: 45934 | C37: Las Overas | D37: Tomas | E37: 265 | F37: 236 | G37: =F37*0.904615384615384 -> 213.48923 | H37: =G37-E37 -> -51.510769
B38: 46299 | C38: Costa del Moro | D38: Tomas | E38: 0 | F38: 225 | G38: 225 | H38: =G38-E38 -> 225
B39: 45937 | C39: San Jose | D39: Tomas | E39: 300 | F39: 370 | G39: =F39*0.904615384615384 -> 334.70769 | H39: =G39-E39 -> 34.707692
B40: 45938 | C40: El Ceibo 2 | D40: Paco | E40: 1050 | F40: 208 | G40: =F40*0.904615384615384 -> 188.16 | H40: =G40-E40 -> -861.84
B41: 45938 | C41: El Moro Viejo | D41: Tomas | E41: 263 | F41: 156 | G41: =F41*0.975153846153846 -> 152.124 | H41: =G41-E41 -> -110.876
...

Sheet Gastos
B2: Gastos
H3: GASTO ACTUAL | L3: GASTO REAL | P3: SALDO
H4: Tomas | I4: Paco | L4: Tomas | M4: Paco | P4: Tomas | Q4: Paco
D5: Comun | G5: Total | H5: =SUMIF(E7:E220,H4,D7:D220) -> 66853917 | I5: =SUMIF(E7:E220,I4,D7:D220) -> 45765586 | K5: Total | L5: =D221*Referencias!U7 -> 56309751 | M5: =D221*Referencias!T7 -> 56309751 | O5: Total | P5: =(H5-L5) -> 10544166 | Q5: =(I5-M5) -> -10544166
B6: Fecha | C6: Concepto | D6: Importe | E6: Aporte
C7: Movilidad no cobrada | D7: =Viajes!S5 -> 6687951.2 | E7: Tomas
C8: Movilidad no cobrada | D8: =Viajes!T5 -> 6037207.7 | E8: Paco
B9: 45912 | C9: Impresión folletos | D9: 20000 | E9: Paco
B10: 45912 | C10: Clavos y platos | D10: 19000 | E10: Tomas
B11: 45916 | C11: Pago Facundo Kaplun | D11: 120000 | E11: Tomas
B12: 45917 | C12: Pago Agustin Acosta | D12: 150000 | E12: Tomas
B13: 45918 | C13: Pago Alexis Marsico | D13: 150000 | E13: Paco
B14: 45919 | C14: Impresión planillas | D14: 14200 | E14: Tomas
B15: 45919 | C15: Aros monitoreo | D15: 11500 | E15: Tomas
B16: 45922 | C16: Alojamiento Tandil | D16: 442500 | E16: Paco
B17: 45922 | C17: Alojamiento Tandil | D17: 73700 | E17: Paco
B18: 45922 | C18: Super Tandil | D18: 35692.26 | E18: Paco
B19: 45923 | C19: Super Tandil | D19: 44113.6 | E19: Paco
B20: 45923 | C20: Pago Facundo Kaplun | D20: 150000 | E20: Tomas
... B145: 46040 | C145: Pago Melanie Verkuyl | D145: 233376 | E145: Tomas
C146: Monotributo 09 | D146: 391400.62 | E146: Tomas
C147: Monotributo 09 | D147: 49435.58 | E147: Tomas
C148: Monotributo 09 | D148: 391400.62 | E148: Paco
C149: Monotributo 10 | D149: 391400.62 | E149: Tomas
C150: Monotributo 10 | D150: 49435.58 | E150: Tomas
C151: Monotributo 10 | D151: 391400.62 | E151: Paco
C152: Monotributo 11 | D152: 391400.62 | E152: Tomas
C153: Monotributo 11 | D153: 49435.58 | E153: Tomas
C154: Monotributo 11 | D154: 391400.62 | E154: Paco
C155: Monotributo 12 | D155: 172457.38 | E155: Tomas
C156: Monotributo 12 | D156: 49435.58 | E156: Tomas
C157: Monotributo 12 | D157: 391400.62 | E157: Paco
... C161: Monotributo 01 | D161: 391400.62 | E161: Paco
B162: 46041 | C162: Honorarios Kaspar (sep) | D162: 57000 | E162: Tomas
B163: 46041 | C163: Honorarios Kaspar (oct) | D163: 58000 | E163: Tomas
B164: 46041 | C164: Honorarios Kaspar (nov) | D164: 59000 | E164: Tomas
B165: 46041 | C165: Honorarios Kaspar (dic) | D165: 60400 | E165: Tomas
C166: Monotributo 02 | D166: 999007.65 | E166: Tomas
C167: Monotributo 02 | D167: 447346.93 | E167: Tomas
C168: Monotributo 02 | D168: 447346.93 | E168: Paco
...

Sheet Saldos
B2: Saldos
B4: Cod. Cliente | C4: Cliente | D4: Total | E4: Cobrado | F4: Saldo | G4: Detalle enviado | H4: Facturado | I4: Cobrado
B5: 1 | C5: =IFERROR(VLOOKUP(B5,Referencias!$B$7:$C$154,2,FALSE),"") -> Daniel Lanz | D5: =SUMIF(Trabajos!$E$5:$E$394,B5,Trabajos!$P$5:$P$394)+SUMIF('Trabajos 2'!$E$5:$E$156,B5,'Trabajos 2'!$P$5:$P$156) -> 0 | E5: =SUMIF(Ingresos!$C$6:$C$115,B5,Ingresos!$E$6:$E$115) -> 0 | F5: =E5-D5 -> 0
B6: 2 | C6: =IFERROR(VLOOKUP(B6,Referencias!$B$7:$C$154,2,FALSE),"") -> Land Management | D6: =SUMIF(Trabajos!$E$5:$E$394,B6,Trabajos!$P$5:$P$394)+SUMIF('Trabajos 2'!$E$5:$E$156,B6,'Trabajos 2'!$P$5:$P$156) -> 0 | E6: =SUMIF(Ingresos!$C$6:$C$115,B6,Ingresos!$E$6:$E$115) -> 0 | F6: =E6-D6 -> 0
B7: 3 | C7: =IFERROR(VLOOKUP(B7,Referencias!$B$7:$C$154,2,FALSE),"") -> Martin Santamaria | D7: =SUMIF(Trabajos!$E$5:$E$394,B7,Trabajos!$P$5:$P$394)+SUMIF('Trabajos 2'!$E$5:$E$156,B7,'Trabajos 2'!$P$5:$P$156) -> 0 | E7: =SUMIF(Ingresos!$C$6:$C$115,B7,Ingresos!$E$6:$E$115) -> 0 | F7: =E7-D7 -> 0
B8: 4 | C8: =IFERROR(VLOOKUP(B8,Referencias!$B$7:$C$154,2,FALSE),"") -> Purtierra | D8: =SUMIF(Trabajos!$E$5:$E$394,B8,Trabajos!$P$5:$P$394)+SUMIF('Trabajos 2'!$E$5:$E$156,B8,'Trabajos 2'!$P$5:$P$156) -> 3324804 | E8: =SUMIF(Ingresos!$C$6:$C$115,B8,Ingresos!$E$6:$E$115) -> 3324804 | F8: =E8-D8 -> 0
B9: 5 | C9: =IFERROR(VLOOKUP(B9,Referencias!$B$7:$C$154,2,FALSE),"") -> Cofina Agro | D9: =SUMIF(Trabajos!$E$5:$E$394,B9,Trabajos!$P$5:$P$394)+SUMIF('Trabajos 2'!$E$5:$E$156,B9,'Trabajos 2'!$P$5:$P$156) -> 1704025 | E9: =SUMIF(Ingresos!$C$6:$C$115,B9,Ingresos!$E$6:$E$115) -> 1704025 | F9: =E9-D9 -> 0
B10: 6 | C10: =IFERROR(VLOOKUP(B10,Referencias!$B$7:$C$154,2,FALSE),"") -> La Nany S.A. | D10: =SUMIF(Trabajos!$E$5:$E$394,B10,Trabajos!$P$5:$P$394)+SUMIF('Trabajos 2'!$E$5:$E$156,B10,'Trabajos 2'!$P$5:$P$156) -> 6135499.8 | E10: =SUMIF(Ingresos!$C$6:$C$115,B10,Ingresos!$E$6:$E$115) -> 6135499.8 | F10: =E10-D10 -> 0
B11: 7 | C11: =IFERROR(VLOOKUP(B11,Referencias!$B$7:$C$154,2,FALSE),"") -> Agrar del Sur | D11: =SUMIF(Trabajos!$E$5:$E$394,B11,Trabajos!$P$5:$P$394)+SUMIF('Trabajos 2'!$E$5:$E$156,B11,'Trabajos 2'!$P$5:$P$156) -> 0 | E11: =SUMIF(Ingresos!$C$6:$C$115,B11,Ingresos!$E$6:$E$115) -> 0 | F11: =E11-D11 -> 0
B12: 8 | C12: =IFERROR(VLOOKUP(B12,Referencias!$B$7:$C$154,2,FALSE),"") -> Baltan Agropecuaria | D12: =SUMIF(Trabajos!$E$5:$E$394,B12,Trabajos!$P$5:$P$394)+SUMIF('Trabajos 2'!$E$5:$E$156,B12,'Trabajos 2'!$P$5:$P$156) -> 556973.25 | E12: =SUMIF(Ingresos!$C$6:$C$115,B12,Ingresos!$E$6:$E$115) -> 556973.25 | F12: =E12-D12 -> 0
B13: 9 | C13: =IFERROR(VLOOKUP(B13,Referencias!$B$7:$C$154,2,FALSE),"") -> Alberto Oscar Moran | D13: =SUMIF(Trabajos!$E$5:$E$394,B13,Trabajos!$P$5:$P$394)+SUMIF('Trabajos 2'!$E$5:$E$156,B13,'Trabajos 2'!$P$5:$P$156) -> 0 | E13: =SUMIF(Ingresos!$C$6:$C$115,B13,Ingresos!$E$6:$E$115) -> 0 | F13: =E13-D13 -> 0
B14: 10 | C14: =IFERROR(VLOOKUP(B14,Referencias!$B$7:$C$154,2,FALSE),"") -> Tibus S.A. | D14: =SUMIF(Trabajos!$E$5:$E$394,B14,Trabajos!$P$5:$P$394)+SUMIF('Trabajos 2'!$E$5:$E$156,B14,'Trabajos 2'!$P$5:$P$156) -> 0 | E14: =SUMIF(Ingresos!$C$6:$C$115,B14,Ingresos!$E$6:$E$115) -> 0 | F14: =E14-D14 -> 0
B15: 11 | C15: =IFERROR(VLOOKUP(B15,Referencias!$B$7:$C$154,2,FALSE),"") -> Carlos Fernando Fuertes | D15: =SUMIF(Trabajos!$E$5:$E$394,B15,Trabajos!$P$5:$P$394)+SUMIF('Trabajos 2'!$E$5:$E$156,B15,'Trabajos 2'!$P$5:$P$156) -> 6095260 | E15: =SUMIF(Ingresos!$C$6:$C$115,B15,Ingresos!$E$6:$E$115) -> 5033260 | F15: =E15-D15 -> -1062000
B16: 12 | C16: =IFERROR(VLOOKUP(B16,Referencias!$B$7:$C$154,2,FALSE),"") -> Miron y Alfonso/Iocco Palladino | D16: =SUMIF(Trabajos!$E$5:$E$394,B16,Trabajos!$P$5:$P$394)+SUMIF('Trabajos 2'!$E$5:$E$156,B16,'Trabajos 2'!$P$5:$P$156) -> 0 | E16: =SUMIF(Ingresos!$C$6:$C$115,B16,Ingresos!$E$6:$E$115) -> 0 | F16: =E16-D16 -> 0
... B27: 23 | C27: =IFERROR(VLOOKUP(B27,Referencias!$B$7:$C$154,2,FALSE),"") -> Esteban Dominguez | D27: =SUMIF(Trabajos!$E$5:$E$394,B27,Trabajos!$P$5:$P$394)+SUMIF('Trabajos 2'!$E$5:$E$156,B27,'Trabajos 2'!$P$5:$P$156) -> 0 | E27: =SUMIF(Ingresos!$C$6:$C$115,B27,Ingresos!$E$6:$E$115) -> 0 | F27: =E27-D27 -> 0
B28: 24 | C28: =IFERROR(VLOOKUP(B28,Referencias!$B$7:$C$154,2,FALSE),"") -> Nugas S.A. | D28: =SUMIF(Trabajos!$E$5:$E$394,B28,Trabajos!$P$5:$P$394)+SUMIF('Trabajos 2'!$E$5:$E$156,B28,'Trabajos 2'!$P$5:$P$156) -> 9539896.2 | E28: =SUMIF(Ingresos!$C$6:$C$115,B28,Ingresos!$E$6:$E$115) -> 8855343.2 | F28: =E28-D28 -> -684553 | G28: Si | H28: Si
B29: 25 | C29: =IFERROR(VLOOKUP(B29,Referencias!$B$7:$C$154,2,FALSE),"") -> Hugo Pascual | D29: =SUMIF(Trabajos!$E$5:$E$394,B29,Trabajos!$P$5:$P$394)+SUMIF('Trabajos 2'!$E$5:$E$156,B29,'Trabajos 2'!$P$5:$P$156) -> 0 | E29: =SUMIF(Ingresos!$C$6:$C$115,B29,Ingresos!$E$6:$E$115) -> 0 | F29: =E29-D29 -> 0
B30: 26 | C30: =IFERROR(VLOOKUP(B30,Referencias!$B$7:$C$154,2,FALSE),"") -> Oxagro S.A. | D30: =SUMIF(Trabajos!$E$5:$E$394,B30,Trabajos!$P$5:$P$394)+SUMIF('Trabajos 2'!$E$5:$E$156,B30,'Trabajos 2'!$P$5:$P$156) -> 0 | E30: =SUMIF(Ingresos!$C$6:$C$115,B30,Ingresos!$E$6:$E$115) -> 0 | F30: =E30-D30 -> 0
B31: 27 | C31: =IFERROR(VLOOKUP(B31,Referencias!$B$7:$C$154,2,FALSE),"") -> Biocrop S.A. | D31: =SUMIF(Trabajos!$E$5:$E$394,B31,Trabajos!$P$5:$P$394)+SUMIF('Trabajos 2'!$E$5:$E$156,B31,'Trabajos 2'!$P$5:$P$156) -> 0 | E31: =SUMIF(Ingresos!$C$6:$C$115,B31,Ingresos!$E$6:$E$115) -> 0 | F31: =E31-D31 -> 0
B32: 28 | C32: =IFERROR(VLOOKUP(B32,Referencias!$B$7:$C$154,2,FALSE),"") -> Agroproductos | D32: =SUMIF(Trabajos!$E$5:$E$394,B32,Trabajos!$P$5:$P$394)+SUMIF('Trabajos 2'!$E$5:$E$156,B32,'Trabajos 2'!$P$5:$P$156) -> 0 | E32: =SUMIF(Ingresos!$C$6:$C$115,B32,Ingresos!$E$6:$E$115) -> 0 | F32: =E32-D32 -> 0
B33: 29 | C33: =IFERROR(VLOOKUP(B33,Referencias!$B$7:$C$154,2,FALSE),"") -> Parceiros Sul America S.A. | D33: =SUMIF(Trabajos!$E$5:$E$394,B33,Trabajos!$P$5:$P$394)+SUMIF('Trabajos 2'!$E$5:$E$156,B33,'Trabajos 2'!$P$5:$P$156) -> 0 | E33: =SUMIF(Ingresos!$C$6:$C$115,B33,Ingresos!$E$6:$E$115) -> 0 | F33: =E33-D33 -> 0
B34: 30 | C34: =IFERROR(VLOOKUP(B34,Referencias!$B$7:$C$154,2,FALSE),"") -> Estancia San Pedro S.A. | D34: =SUMIF(Trabajos!$E$5:$E$394,B34,Trabajos!$P$5:$P$394)+SUMIF('Trabajos 2'!$E$5:$E$156,B34,'Trabajos 2'!$P$5:$P$156) -> 0 | E34: =SUMIF(Ingresos!$C$6:$C$115,B34,Ingresos!$E$6:$E$115) -> 0 | F34: =E34-D34 -> 0
B35: 31 | C35: =IFERROR(VLOOKUP(B35,Referencias!$B$7:$C$154,2,FALSE),"") -> La Gloriosa S.A. | D35: =SUMIF(Trabajos!$E$5:$E$394,B35,Trabajos!$P$5:$P$394)+SUMIF('Trabajos 2'!$E$5:$E$156,B35,'Trabajos 2'!$P$5:$P$156) -> 4355350.3 | E35: =SUMIF(Ingresos!$C$6:$C$115,B35,Ingresos!$E$6:$E$115) -> 3316863.9 | F35: =E35-D35 -> -1038486.4 | G35: Si | H35: Si
B36: 32 | C36: =IFERROR(VLOOKUP(B36,Referencias!$B$7:$C$154,2,FALSE),"") -> Sebastian Pascualini | D36: =SUMIF(Trabajos!$E$5:$E$394,B36,Trabajos!$P$5:$P$394)+SUMIF('Trabajos 2'!$E$5:$E$156,B36,'Trabajos 2'!$P$5:$P$156) -> 0 | E36: =SUMIF(Ingresos!$C$6:$C$115,B36,Ingresos!$E$6:$E$115) -> 0 | F36: =E36-D36 -> 0
B37: 33 | C37: =IFERROR(VLOOKUP(B37,Referencias!$B$7:$C$154,2,FALSE),"") -> Espartina S.A. | D37: =SUMIF(Trabajos!$E$5:$E$394,B37,Trabajos!$P$5:$P$394)+SUMIF('Trabajos 2'!$E$5:$E$156,B37,'Trabajos 2'!$P$5:$P$156) -> 1.4754476e+08 | E37: =SUMIF(Ingresos!$C$6:$C$115,B37,Ingresos!$E$6:$E$115) -> 1.4722941e+08 | F37: =E37-D37 -> -315348 | G37: No | H37: No
B38: 34 | C38: =IFERROR(VLOOKUP(B38,Referencias!$B$7:$C$154,2,FALSE),"") -> Garfin Agro S.A. | D38: =SUMIF(Trabajos!$E$5:$E$394,B38,Trabajos!$P$5:$P$394)+SUMIF('Trabajos 2'!$E$5:$E$156,B38,'Trabajos 2'!$P$5:$P$156) -> 0 | E38: =SUMIF(Ingresos!$C$6:$C$115,B38,Ingresos!$E$6:$E$115) -> 0 | F38: =E38-D38 -> 0
B39: 35 | C39: =IFERROR(VLOOKUP(B39,Referencias!$B$7:$C$154,2,FALSE),"") -> Federico Sturla | D39: =SUMIF(Trabajos!$E$5:$E$394,B39,Trabajos!$P$5:$P$394)+SUMIF('Trabajos 2'!$E$5:$E$156,B39,'Trabajos 2'!$P$5:$P$156) -> 0 | E39: =SUMIF(Ingresos!$C$6:$C$115,B39,Ingresos!$E$6:$E$115) -> 0 | F39: =E39-D39 -> 0
B40: 36 | C40: =IFERROR(VLOOKUP(B40,Referencias!$B$7:$C$154,2,FALSE),"") -> Don Balbino | D40: =SUMIF(Trabajos!$E$5:$E$394,B40,Trabajos!$P$5:$P$394)+SUMIF('Trabajos 2'!$E$5:$E$156,B40,'Trabajos 2'!$P$5:$P$156) -> 0 | E40: =SUMIF(Ingresos!$C$6:$C$115,B40,Ingresos!$E$6:$E$115) -> 0 | F40: =E40-D40 -> 0
B41: 37 | C41: =IFERROR(VLOOKUP(B41,Referencias!$B$7:$C$154,2,FALSE),"") -> Sebastian Martos | D41: =SUMIF(Trabajos!$E$5:$E$394,B41,Trabajos!$P$5:$P$394)+SUMIF('Trabajos 2'!$E$5:$E$156,B41,'Trabajos 2'!$P$5:$P$156) -> 2136755 | E41: =SUMIF(Ingresos!$C$6:$C$115,B41,Ingresos!$E$6:$E$115) -> 2136755 | F41: =E41-D41 -> 0
B42: 38 | C42: =IFERROR(VLOOKUP(B42,Referencias!$B$7:$C$154,2,FALSE),"") -> Julio Bertoloto | D42: =SUMIF(Trabajos!$E$5:$E$394,B42,Trabajos!$P$5:$P$394)+SUMIF('Trabajos 2'!$E$5:$E$156,B42,'Trabajos 2'!$P$5:$P$156) -> 0 | E42: =SUMIF(Ingresos!$C$6:$C$115,B42,Ingresos!$E$6:$E$115) -> 0 | F42: =E42-D42 -> 0
B43: 39 | C43: =IFERROR(VLOOKUP(B43,Referencias!$B$7:$C$154,2,FALSE),"") -> Fabian Trama | D43: =SUMIF(Trabajos!$E$5:$E$394,B43,Trabajos!$P$5:$P$394)+SUMIF('Trabajos 2'!$E$5:$E$156,B43,'Trabajos 2'!$P$5:$P$156) -> 0 | E43: =SUMIF(Ingresos!$C$6:$C$115,B43,Ingresos!$E$6:$E$115) -> 0 | F43: =E43-D43 -> 0
B44: 40 | C44: =IFERROR(VLOOKUP(B44,Referencias!$B$7:$C$154,2,FALSE),"") -> Cía. de Tierras Sud Argentino S.A. | D44: =SUMIF(Trabajos!$E$5:$E$394,B44,Trabajos!$P$5:$P$394)+SUMIF('Trabajos 2'!$E$5:$E$156,B44,'Trabajos 2'!$P$5:$P$156) -> 17307389 | E44: =SUMIF(Ingresos!$C$6:$C$115,B44,Ingresos!$E$6:$E$115) -> 17307389 | F44: =E44-D44 -> 0
B45: 41 | C45: =IFERROR(VLOOKUP(B45,Referencias!$B$7:$C$154,2,FALSE),"") -> Cresud S.A.C.I.F y A | D45: =SUMIF(Trabajos!$E$5:$E$394,B45,Trabajos!$P$5:$P$394)+SUMIF('Trabajos 2'!$E$5:$E$156,B45,'Trabajos 2'!$P$5:$P$156) -> 0 | E45: =SUMIF(Ingresos!$C$6:$C$115,B45,Ingresos!$E$6:$E$115) -> 0 | F45: =E45-D45 -> 0
B46: 42 | C46: =IFERROR(VLOOKUP(B46,Referencias!$B$7:$C$154,2,FALSE),"") -> Juan Carlos Naveira | D46: =SUMIF(Trabajos!$E$5:$E$394,B46,Trabajos!$P$5:$P$394)+SUMIF('Trabajos 2'!$E$5:$E$156,B46,'Trabajos 2'!$P$5:$P$156) -> 0 | E46: =SUMIF(Ingresos!$C$6:$C$115,B46,Ingresos!$E$6:$E$115) -> 0 | F46: =E46-D46 -> 0
B47: 43 | C47: =IFERROR(VLOOKUP(B47,Referencias!$B$7:$C$154,2,FALSE),"") -> Anuitt S.R.L | D47: =SUMIF(Trabajos!$E$5:$E$394,B47,Trabajos!$P$5:$P$394)+SUMIF('Trabajos 2'!$E$5:$E$156,B47,'Trabajos 2'!$P$5:$P$156) -> 0 | E47: =SUMIF(Ingresos!$C$6:$C$115,B47,Ingresos!$E$6:$E$115) -> 0 | F47: =E47-D47 -> 0
B48: 44 | C48: =IFERROR(VLOOKUP(B48,Referencias!$B$7:$C$154,2,FALSE),"") -> Francisco Hernandez | D48: =SUMIF(Trabajos!$E$5:$E$394,B48,Trabajos!$P$5:$P$394)+SUMIF('Trabajos 2'!$E$5:$E$156,B48,'Trabajos 2'!$P$5:$P$156) -> 0 | E48: =SUMIF(Ingresos!$C$6:$C$115,B48,Ingresos!$E$6:$E$115) -> 0 | F48: =E48-D48 -> 0
B49: 45 | C49: =IFERROR(VLOOKUP(B49,Referencias!$B$7:$C$154,2,FALSE),"") -> Guillermo Pugliese | D49: =SUMIF(Trabajos!$E$5:$E$394,B49,Trabajos!$P$5:$P$394)+SUMIF('Trabajos 2'!$E$5:$E$156,B49,'Trabajos 2'!$P$5:$P$156) -> 4286937.6 | E49: =SUMIF(Ingresos!$C$6:$C$115,B49,Ingresos!$E$6:$E$115) -> 4286937.6 | F49: =E49-D49 -> 0
... B85: 81 | C85: =IFERROR(VLOOKUP(B85,Referencias!$B$7:$C$154,2,FALSE),"") -> Santiago Chevalier | D85: =SUMIF(Trabajos!$E$5:$E$394,B85,Trabajos!$P$5:$P$394)+SUMIF('Trabajos 2'!$E$5:$E$156,B85,'Trabajos 2'!$P$5:$P$156) -> 0 | E85: =SUMIF(Ingresos!$C$6:$C$115,B85,Ingresos!$E$6:$E$115) -> 0 | F85: =E85-D85 -> 0
B86: 82 | C86: =IFERROR(VLOOKUP(B86,Referencias!$B$7:$C$154,2,FALSE),"") -> Cristian Rybner | D86: =SUMIF(Trabajos!$E$5:$E$394,B86,Trabajos!$P$5:$P$394)+SUMIF('Trabajos 2'!$E$5:$E$156,B86,'Trabajos 2'!$P$5:$P$156) -> 473973.5 | E86: =SUMIF(Ingresos!$C$6:$C$115,B86,Ingresos!$E$6:$E$115) -> 0 | F86: =E86-D86 -> -473973.5 | G86: Si | H86: Si
B87: 83 | C87: =IFERROR(VLOOKUP(B87,Referencias!$B$7:$C$154,2,FALSE),"") -> Eduardo Nasurdi | D87: =SUMIF(Trabajos!$E$5:$E$394,B87,Trabajos!$P$5:$P$394)+SUMIF('Trabajos 2'!$E$5:$E$156,B87,'Trabajos 2'!$P$5:$P$156) -> 0 | E87: =SUMIF(Ingresos!$C$6:$C$115,B87,Ingresos!$E$6:$E$115) -> 0 | F87: =E87-D87 -> 0
...

Sheet Ingresos
B2: Ingresos | K2: Movimientos
P3: Ingreso por facturacion | S3: Saldo movimientos | V3: Ingreso percibido | Y3: Ingreso total a percibir | AB3: Gastos | AE3: Saldo ingreso
P4: Paco | Q4: Tomas | S4: Paco | T4: Tomas | V4: Paco | W4: Tomas | Y4: Paco | Z4: Tomas | AB4: Paco | AC4: Tomas | AE4: Paco | AF4: Tomas
B5: Fecha | C5: Cod. Cliente | D5: Cliente | E5: Importe | F5: IVA | G5: Impuestos | H5: Total | I5: Cobrado | K5: Fecha | L5: De | M5: Para | N5: Importe | P5: =SUMIF(I6:I115,P4,H6:H115) -> 79185150 | Q5: =SUMIF(I6:I115,Q4,H6:H115) -> 1.6823207e+08 | S5: =(SUMIF(M6:M116,S4,N6:N116)-SUMIF(L6:L116,S4,N6:N116)) -> 25300000 | T5: =(SUMIF(M6:M116,T4,N6:N116)-SUMIF(L6:L116,T4,N6:N116)) -> -25300000 | V5: =P5+S5 -> 1.0448515e+08 | W5: =Q5+T5 -> 1.4293207e+08 | Y5: =IFERROR(Asignación!O8+'Asignación 2'!O8,"") -> 1.1064992e+08 | Z5: =IFERROR(Asignación!P8+'Asignación 2'!P8,"") -> 1.2553274e+08 | AB5: =Gastos!Q5 -> -10544166 | AC5: =Gastos!P5 -> 10544166 | AE5: =Y5-V5+AB5 -> -4379393.4 | AF5: =Z5-W5+AC5 -> -6855169.1
B6: 45947 | C6: 76 | D6: =IFERROR(VLOOKUP(C6,Referencias!$B$7:$C$154,2,FALSE),"") -> Bruno Fioriti | E6: 734290 | H6: =IF(E6<>"",E6-E6*G6,"") -> 734290 | I6: Tomas | K6: 45946 | L6: Paco | M6: Tomas | N6: 200000
B7: 45954 | C7: 50 | D7: =IFERROR(VLOOKUP(C7,Referencias!$B$7:$C$154,2,FALSE),"") -> Mackrey Agropecuaria | E7: 153100 | H7: =IF(E7<>"",E7-E7*G7,"") -> 153100 | I7: Tomas | K7: 46016 | L7: Tomas | M7: Paco | N7: 700000 | AE7: =1-(AE5/Y5) -> 1.0395788 | AF7: =1-(AF5/Z5) -> 1.0546086
B8: 45954 | C8: 33 | D8: =IFERROR(VLOOKUP(C8,Referencias!$B$7:$C$154,2,FALSE),"") -> Espartina S.A. | E8: 4313044.7 | H8: =IF(E8<>"",E8-E8*G8,"") -> 4313044.7 | I8: Tomas | K8: 46383 | L8: Tomas | M8: Paco | N8: 800000
B9: 45961 | C9: 17 | D9: =IFERROR(VLOOKUP(C9,Referencias!$B$7:$C$154,2,FALSE),"") -> Campo Maipu S.A. | E9: 1428485 | H9: =IF(E9<>"",E9-E9*G9,"") -> 1428485 | I9: Tomas | K9: 46024 | L9: Tomas | M9: Paco | N9: 1500000
B10: 45979 | C10: 98 | D10: =IFERROR(VLOOKUP(C10,Referencias!$B$7:$C$154,2,FALSE),"") -> Inalco | E10: 1118625 | H10: =IF(E10<>"",E10-E10*G10,"") -> 1118625 | I10: Paco | K10: 46024 | L10: Tomas | M10: Paco | N10: 1500000
B11: 45952 | C11: 33 | D11: =IFERROR(VLOOKUP(C11,Referencias!$B$7:$C$154,2,FALSE),"") -> Espartina S.A. | E11: 2488971.7 | H11: =IF(E11<>"",E11-E11*G11,"") -> 2488971.7 | I11: Paco | K11: 46027 | L11: Tomas | M11: Paco | N11: 2000000
B12: 45967 | C12: 33 | D12: =IFERROR(VLOOKUP(C12,Referencias!$B$7:$C$154,2,FALSE),"") -> Espartina S.A. | E12: 4687421.8 | H12: =IF(E12<>"",E12-E12*G12,"") -> 4687421.8 | I12: Paco | K12: 46027 | L12: Tomas | M12: Paco | N12: 2000000
B13: 45983 | C13: 33 | D13: =IFERROR(VLOOKUP(C13,Referencias!$B$7:$C$154,2,FALSE),"") -> Espartina S.A. | E13: 6095843.2 | H13: =IF(E13<>"",E13-E13*G13,"") -> 6095843.2 | I13: Paco | K13: 46043 | L13: Tomas | M13: Paco | N13: 15500000
B14: 45952 | C14: 33 | D14: =IFERROR(VLOOKUP(C14,Referencias!$B$7:$C$154,2,FALSE),"") -> Espartina S.A. | E14: 6284493.5 | H14: =IF(E14<>"",E14-E14*G14,"") -> 6284493.5 | I14: Tomas | K14: 46225 | L14: Tomas | M14: Paco | N14: 1500000
B15: 45962 | C15: 40 | D15: =IFERROR(VLOOKUP(C15,Referencias!$B$7:$C$154,2,FALSE),"") -> Cía. de Tierras Sud Argentino S.A. | E15: 4628250 | H15: =IF(E15<>"",E15-E15*G15,"") -> 4628250 | I15: Tomas
B16: 45980 | C16: 118 | D16: =IFERROR(VLOOKUP(C16,Referencias!$B$7:$C$154,2,FALSE),"") -> Juan Ignacio Franco | E16: 668347.5 | H16: =IF(E16<>"",E16-E16*G16,"") -> 668347.5 | I16: Tomas
B17: 45989 | C17: 4 | D17: =IFERROR(VLOOKUP(C17,Referencias!$B$7:$C$154,2,FALSE),"") -> Purtierra | E17: 955000 | H17: =IF(E17<>"",E17-E17*G17,"") -> 955000 | I17: Tomas
B18: 45989 | C18: 4 | D18: =IFERROR(VLOOKUP(C18,Referencias!$B$7:$C$154,2,FALSE),"") -> Purtierra | E18: 955000 | H18: =IF(E18<>"",E18-E18*G18,"") -> 955000 | I18: Paco
B19: 45989 | C19: 124 | D19: =IFERROR(VLOOKUP(C19,Referencias!$B$7:$C$154,2,FALSE),"") -> Cristian Perez Maraviglia | E19: 131541.25 | H19: =IF(E19<>"",E19-E19*G19,"") -> 131541.25 | I19: Tomas
B20: 45989 | C20: 124 | D20: =IFERROR(VLOOKUP(C20,Referencias!$B$7:$C$154,2,FALSE),"") -> Cristian Perez Maraviglia | E20: 131541.25 | H20: =IF(E20<>"",E20-E20*G20,"") -> 131541.25 | I20: Paco
B21: 45989 | C21: 6 | D21: =IFERROR(VLOOKUP(C21,Referencias!$B$7:$C$154,2,FALSE),"") -> La Nany S.A. | E21: 2000000 | H21: =IF(E21<>"",E21-E21*G21,"") -> 2000000 | I21: Tomas
B22: 45992 | C22: 122 | D22: =IFERROR(VLOOKUP(C22,Referencias!$B$7:$C$154,2,FALSE),"") -> Martin Juarez | E22: 133830 | H22: =IF(E22<>"",E22-E22*G22,"") -> 133830 | I22: Paco
B23: 45992 | C23: 122 | D23: =IFERROR(VLOOKUP(C23,Referencias!$B$7:$C$154,2,FALSE),"") -> Martin Juarez | E23: 646642 | H23: =IF(E23<>"",E23-E23*G23,"") -> 646642 | I23: Paco
B24: 45992 | C24: 125 | D24: =IFERROR(VLOOKUP(C24,Referencias!$B$7:$C$154,2,FALSE),"") -> Soledad Gutierrez | E24: 585600 | H24: =IF(E24<>"",E24-E24*G24,"") -> 585600 | I24: Tomas
B25: 45993 | C25: 126 | D25: =IFERROR(VLOOKUP(C25,Referencias!$B$7:$C$154,2,FALSE),"") -> Patricia Ricci | E25: 509662.5 | H25: =IF(E25<>"",E25-E25*G25,"") -> 509662.5 | I25: Tomas
B26: 45994 | C26: 6 | D26: =IFERROR(VLOOKUP(C26,Referencias!$B$7:$C$154,2,FALSE),"") -> La Nany S.A. | E26: 3395993.8 | H26: =IF(E26<>"",E26-E26*G26,"") -> 3395993.8 | I26: Tomas
... B104: 46227 | C104: 33 | D104: =IFERROR(VLOOKUP(C104,Referencias!$B$7:$C$154,2,FALSE),"") -> Espartina S.A. | E104: 1780952.4 | H104: =IF(E104<>"",E104-E104*G104,"") -> 1780952.4 | I104: Tomas
D105: =IFERROR(VLOOKUP(C105,Referencias!$B$7:$C$154,2,FALSE),"") | H105: =IF(E105<>"",E105-E105*G105,"")
D106: =IFERROR(VLOOKUP(C106,Referencias!$B$7:$C$154,2,FALSE),"") | H106: =IF(E106<>"",E106-E106*G106,"")
D107: =IFERROR(VLOOKUP(C107,Referencias!$B$7:$C$154,2,FALSE),"") | H107: =IF(E107<>"",E107-E107*G107,"")
D108: =IFERROR(VLOOKUP(C108,Referencias!$B$7:$C$154,2,FALSE),"") | H108: =IF(E108<>"",E108-E108*G108,"")
D109: =IFERROR(VLOOKUP(C109,Referencias!$B$7:$C$154,2,FALSE),"") | H109: =IF(E109<>"",E109-E109*G109,"")
D110: =IFERROR(VLOOKUP(C110,Referencias!$B$7:$C$154,2,FALSE),"") | H110: =IF(E110<>"",E110-E110*G110,"")
D111: =IFERROR(VLOOKUP(C111,Referencias!$B$7:$C$154,2,FALSE),"") | H111: =IF(E111<>"",E111-E111*G111,"")
D112: =IFERROR(VLOOKUP(C112,Referencias!$B$7:$C$154,2,FALSE),"") | H112: =IF(E112<>"",E112-E112*G112,"")
D113: =IFERROR(VLOOKUP(C113,Referencias!$B$7:$C$154,2,FALSE),"") | H113: =IF(E113<>"",E113-E113*G113,"")
D114: =IFERROR(VLOOKUP(C114,Referencias!$B$7:$C$154,2,FALSE),"") | H114: =IF(E114<>"",E114-E114*G114,"")
D115: =IFERROR(VLOOKUP(C115,Referencias!$B$7:$C$154,2,FALSE),"") | H115: =IF(E115<>"",E115-E115*G115,"")
B116: Total | E116: =SUM(E6:E115) -> 2.4741722e+08 | H116: =SUM(H6:H115) -> 2.4741722e+08

Sheet Empleados
B2: Empleados
H3: =SUBTOTAL(9,H5:H415) -> 38775952
B4: Fecha | C4: Nombre | D4: Jornada | E4: Valor | F4: Km | G4: Valor | H4: Total | J4: Empleado | K4: Ingreso
B5: 45912 | C5: Agustin Acosta | D5: 1 | E5: 50000 | F5: 291 | G5: 543.3 | H5: =D5*E5+F5*G5 -> 208100.3 | J5: Ezequiel Villar | K5: =SUMIF(C5:C415,J5,H5:H415) -> 300000
B6: 45913 | C6: Juan Manuel Mateos | D6: 1 | E6: 65000 | H6: =D6*E6+F6*G6 -> 65000 | J6: Juan Manuel Mateos | K6: =SUMIF(C5:C415,J6,H5:H415) -> 1870000
B7: 45913 | C7: Facundo Kaplun | D7: 1 | E7: 65000 | F7: 183 | G7: 557.7 | H7: =D7*E7+F7*G7 -> 167059.1 | J7: Martin De Luca | K7: =SUMIF(C5:C415,J7,H5:H415) -> 664521.5
B8: 45913 | C8: Ezequiel Villar | D8: 1 | E8: 50000 | H8: =D8*E8+F8*G8 -> 50000 | J8: Denis Moler | K8: =SUMIF(C5:C415,J8,H5:H415) -> 400000
B9: 45914 | C9: Facundo Kaplun | D9: 1 | E9: 50000 | F9: 14 | G9: 557.7 | H9: =D9*E9+F9*G9 -> 57807.8 | J9: Miguel Rybar | K9: =SUMIF(C5:C415,J9,H5:H415) -> 3242500
B10: 45914 | C10: Denis Moler | D10: 1 | E10: 50000 | H10: =D10*E10+F10*G10 -> 50000 | J10: Damian Diez | K10: =SUMIF(C5:C415,J10,H5:H415) -> 1413487.4
B11: 45914 | C11: Damian Diez | D11: 1 | E11: 65000 | F11: 145 | G11: 633.85 | H11: =D11*E11+F11*G11 -> 156908.25 | J11: Laureano Camino | K11: =SUMIF(C5:C415,J11,H5:H415) -> 150000
B12: 45915 | C12: Facundo Kaplun | D12: 1 | E12: 80000 | F12: 168 | G12: 557.7 | H12: =D12*E12+F12*G12 -> 173693.6 | J12: Pilar Amendola | K12: =SUMIF(C5:C415,J12,H5:H415) -> 465000
B13: 45915 | C13: Juan Manuel Mateos | D13: 1 | E13: 80000 | H13: =D13*E13+F13*G13 -> 80000 | J13: Abelardo Hansen | K13: =SUMIF(C5:C415,J13,H5:H415) -> 1157500
B14: 45915 | C14: Abelardo Hansen | D14: 1 | E14: 80000 | H14: =D14*E14+F14*G14 -> 80000 | J14: Facundo Kaplun | K14: =SUMIF(C5:C415,J14,H5:H415) -> 6572632.1
B15: 45916 | C15: Facundo Kaplun | D15: 1 | E15: 65000 | F15: 395 | G15: 557.7 | H15: =D15*E15+F15*G15 -> 285291.5 | J15: Alexis Marsico | K15: =SUMIF(C5:C415,J15,H5:H415) -> 1975000
B16: 45916 | C16: Juan Manuel Mateos | D16: 1 | E16: 65000 | H16: =D16*E16+F16*G16 -> 65000 | J16: Cecilia Aristemuño | K16: =SUMIF(C5:C415,J16,H5:H415) -> 800000
B17: 45916 | C17: Abelardo Hansen | D17: 1 | E17: 65000 | H17: =D17*E17+F17*G17 -> 65000 | J17: Roberto Cabrera | K17: =SUMIF(C5:C415,J17,H5:H415) -> 150000
B18: 45916 | C18: Alexis Marsico | D18: 1 | E18: 50000 | H18: =D18*E18+F18*G18 -> 50000 | J18: Mateo Mesa | K18: =SUMIF(C5:C415,J18,H5:H415) -> 125000
B19: 45916 | C19: Cecilia Aristemuño | D19: 1 | E19: 50000 | H19: =D19*E19+F19*G19 -> 50000 | J19: Agustin Acosta | K19: =SUMIF(C5:C415,J19,H5:H415) -> 2191918.2
